[2025-04-05T10:29:17.569+0000] {taskinstance.py:1157} INFO - Dependencies all met for dep_context=non-requeueable deps ti=<TaskInstance: news_pipeline.crawl_data manual__2025-04-05T10:29:16.149740+00:00 [queued]>
[2025-04-05T10:29:17.572+0000] {taskinstance.py:1157} INFO - Dependencies all met for dep_context=requeueable deps ti=<TaskInstance: news_pipeline.crawl_data manual__2025-04-05T10:29:16.149740+00:00 [queued]>
[2025-04-05T10:29:17.573+0000] {taskinstance.py:1359} INFO - Starting attempt 1 of 3
[2025-04-05T10:29:17.637+0000] {taskinstance.py:1380} INFO - Executing <Task(PythonOperator): crawl_data> on 2025-04-05 10:29:16.149740+00:00
[2025-04-05T10:29:17.640+0000] {standard_task_runner.py:57} INFO - Started process 372 to run task
[2025-04-05T10:29:17.641+0000] {standard_task_runner.py:84} INFO - Running: ['***', 'tasks', 'run', 'news_pipeline', 'crawl_data', 'manual__2025-04-05T10:29:16.149740+00:00', '--job-id', '1272', '--raw', '--subdir', 'DAGS_FOLDER/news_dags.py', '--cfg-path', '/tmp/tmp2gujd28p']
[2025-04-05T10:29:17.643+0000] {standard_task_runner.py:85} INFO - Job 1272: Subtask crawl_data
[2025-04-05T10:29:17.670+0000] {task_command.py:415} INFO - Running <TaskInstance: news_pipeline.crawl_data manual__2025-04-05T10:29:16.149740+00:00 [running]> on host 351a651d0d83
[2025-04-05T10:29:17.707+0000] {taskinstance.py:1660} INFO - Exporting env vars: AIRFLOW_CTX_DAG_OWNER='***' AIRFLOW_CTX_DAG_ID='news_pipeline' AIRFLOW_CTX_TASK_ID='crawl_data' AIRFLOW_CTX_EXECUTION_DATE='2025-04-05T10:29:16.149740+00:00' AIRFLOW_CTX_TRY_NUMBER='1' AIRFLOW_CTX_DAG_RUN_ID='manual__2025-04-05T10:29:16.149740+00:00'
[2025-04-05T10:29:17.709+0000] {taskinstance.py:1935} ERROR - Task failed with exception
Traceback (most recent call last):
  File "/home/airflow/.local/lib/python3.8/site-packages/airflow/operators/python.py", line 192, in execute
    return_value = self.execute_callable()
  File "/home/airflow/.local/lib/python3.8/site-packages/airflow/operators/python.py", line 209, in execute_callable
    return self.python_callable(*self.op_args, **self.op_kwargs)
  File "/opt/airflow/dags/news_dags.py", line 44, in crawl_task_func
    articles = crawl_vnexpress_ai()
NameError: name 'crawl_vnexpress_ai' is not defined
[2025-04-05T10:29:17.713+0000] {taskinstance.py:1398} INFO - Marking task as UP_FOR_RETRY. dag_id=news_pipeline, task_id=crawl_data, execution_date=20250405T102916, start_date=20250405T102917, end_date=20250405T102917
[2025-04-05T10:29:17.719+0000] {standard_task_runner.py:104} ERROR - Failed to execute job 1272 for task crawl_data (name 'crawl_vnexpress_ai' is not defined; 372)
[2025-04-05T10:29:17.739+0000] {local_task_job_runner.py:228} INFO - Task exited with return code 1
[2025-04-05T10:29:17.752+0000] {taskinstance.py:2776} INFO - 0 downstream tasks scheduled from follow-on schedule check
